2023-12-23 23:29:33,963 - INFO - Assets path configured: E:\npython\PluginBase\assets
2023-12-23 23:29:33,965 - INFO - Starting up TCP server on ('localhost', 61676)
2023-12-23 23:29:33,969 - INFO - App URL: tcp://localhost:61676
2023-12-23 23:29:33,969 - INFO - Connected to Flet app and handling user sessions...
2023-12-23 23:29:33,969 - INFO - Starting Flet View app...
2023-12-23 23:29:33,972 - INFO - Flet View found in: E:\npython\PluginBase\venv\lib\site-packages\flet\bin\flet\flet.exe
2023-12-23 23:29:34,308 - INFO - Session started: 
2023-12-23 23:30:00,501 - ERROR - (cx_Oracle.DatabaseError) ORA-12505: TNS:listener does not currently know of SID given in connect descriptor
(Background on this error at: https://sqlalche.me/e/14/4xp6)
Traceback (most recent call last):
  File "E:\npython\PluginBase\venv\lib\site-packages\sqlalchemy\engine\base.py", line 3371, in _wrap_pool_connect
    return fn()
  File "E:\npython\PluginBase\venv\lib\site-packages\sqlalchemy\pool\base.py", line 327, in connect
    return _ConnectionFairy._checkout(self)
  File "E:\npython\PluginBase\venv\lib\site-packages\sqlalchemy\pool\base.py", line 894, in _checkout
    fairy = _ConnectionRecord.checkout(pool)
  File "E:\npython\PluginBase\venv\lib\site-packages\sqlalchemy\pool\base.py", line 493, in checkout
    rec = pool._do_get()
  File "E:\npython\PluginBase\venv\lib\site-packages\sqlalchemy\pool\impl.py", line 146, in _do_get
    self._dec_overflow()
  File "E:\npython\PluginBase\venv\lib\site-packages\sqlalchemy\util\langhelpers.py", line 70, in __exit__
    compat.raise_(
  File "E:\npython\PluginBase\venv\lib\site-packages\sqlalchemy\util\compat.py", line 211, in raise_
    raise exception
  File "E:\npython\PluginBase\venv\lib\site-packages\sqlalchemy\pool\impl.py", line 143, in _do_get
    return self._create_connection()
  File "E:\npython\PluginBase\venv\lib\site-packages\sqlalchemy\pool\base.py", line 273, in _create_connection
    return _ConnectionRecord(self)
  File "E:\npython\PluginBase\venv\lib\site-packages\sqlalchemy\pool\base.py", line 388, in __init__
    self.__connect()
  File "E:\npython\PluginBase\venv\lib\site-packages\sqlalchemy\pool\base.py", line 691, in __connect
    pool.logger.debug("Error on connect(): %s", e)
  File "E:\npython\PluginBase\venv\lib\site-packages\sqlalchemy\util\langhelpers.py", line 70, in __exit__
    compat.raise_(
  File "E:\npython\PluginBase\venv\lib\site-packages\sqlalchemy\util\compat.py", line 211, in raise_
    raise exception
  File "E:\npython\PluginBase\venv\lib\site-packages\sqlalchemy\pool\base.py", line 686, in __connect
    self.dbapi_connection = connection = pool._invoke_creator(self)
  File "E:\npython\PluginBase\venv\lib\site-packages\sqlalchemy\engine\create.py", line 574, in connect
    return dialect.connect(*cargs, **cparams)
  File "E:\npython\PluginBase\venv\lib\site-packages\sqlalchemy\engine\default.py", line 598, in connect
    return self.dbapi.connect(*cargs, **cparams)
cx_Oracle.DatabaseError: ORA-12505: TNS:listener does not currently know of SID given in connect descriptor

The above exception was the direct cause of the following exception:

Traceback (most recent call last):
  File "E:\npython\PluginBase\app\plug.py", line 43, in run
    data = icls._run_plugin(plugin, data, **{**icls.context, **icls.ENVS[-1]})
  File "E:\npython\PluginBase\app\plug.py", line 55, in _run_plugin
    return plugin.process(data, **kwargs)
  File "E:\npython\PluginBase\app\plugins\\build_in\_ui.py", line 265, in process
    return self.ui("")
  File "E:\npython\PluginBase\app\plugins\\build_in\_ui.py", line 280, in ui
    for item in table.find(key={'like': f"%{key}%"}):
  File "E:\npython\PluginBase\venv\lib\site-packages\dataset\table.py", line 615, in find
    if not self.exists:
  File "E:\npython\PluginBase\venv\lib\site-packages\dataset\table.py", line 57, in exists
    return self.name in self.db
  File "E:\npython\PluginBase\venv\lib\site-packages\dataset\database.py", line 195, in __contains__
    if table_name in self.tables:
  File "E:\npython\PluginBase\venv\lib\site-packages\dataset\database.py", line 184, in tables
    return self.inspect.get_table_names(schema=self.schema)
  File "E:\npython\PluginBase\venv\lib\site-packages\dataset\database.py", line 101, in inspect
    return inspect(self.executable)
  File "E:\npython\PluginBase\venv\lib\site-packages\dataset\database.py", line 89, in executable
    self.connections[tid] = self.engine.connect()
  File "E:\npython\PluginBase\venv\lib\site-packages\sqlalchemy\engine\base.py", line 3325, in connect
    return self._connection_cls(self, close_with_result=close_with_result)
  File "E:\npython\PluginBase\venv\lib\site-packages\sqlalchemy\engine\base.py", line 96, in __init__
    else engine.raw_connection()
  File "E:\npython\PluginBase\venv\lib\site-packages\sqlalchemy\engine\base.py", line 3404, in raw_connection
    return self._wrap_pool_connect(self.pool.connect, _connection)
  File "E:\npython\PluginBase\venv\lib\site-packages\sqlalchemy\engine\base.py", line 3374, in _wrap_pool_connect
    Connection._handle_dbapi_exception_noconnection(
  File "E:\npython\PluginBase\venv\lib\site-packages\sqlalchemy\engine\base.py", line 2208, in _handle_dbapi_exception_noconnection
    util.raise_(
  File "E:\npython\PluginBase\venv\lib\site-packages\sqlalchemy\util\compat.py", line 211, in raise_
    raise exception
  File "E:\npython\PluginBase\venv\lib\site-packages\sqlalchemy\engine\base.py", line 3371, in _wrap_pool_connect
    return fn()
  File "E:\npython\PluginBase\venv\lib\site-packages\sqlalchemy\pool\base.py", line 327, in connect
    return _ConnectionFairy._checkout(self)
  File "E:\npython\PluginBase\venv\lib\site-packages\sqlalchemy\pool\base.py", line 894, in _checkout
    fairy = _ConnectionRecord.checkout(pool)
  File "E:\npython\PluginBase\venv\lib\site-packages\sqlalchemy\pool\base.py", line 493, in checkout
    rec = pool._do_get()
  File "E:\npython\PluginBase\venv\lib\site-packages\sqlalchemy\pool\impl.py", line 146, in _do_get
    self._dec_overflow()
  File "E:\npython\PluginBase\venv\lib\site-packages\sqlalchemy\util\langhelpers.py", line 70, in __exit__
    compat.raise_(
  File "E:\npython\PluginBase\venv\lib\site-packages\sqlalchemy\util\compat.py", line 211, in raise_
    raise exception
  File "E:\npython\PluginBase\venv\lib\site-packages\sqlalchemy\pool\impl.py", line 143, in _do_get
    return self._create_connection()
  File "E:\npython\PluginBase\venv\lib\site-packages\sqlalchemy\pool\base.py", line 273, in _create_connection
    return _ConnectionRecord(self)
  File "E:\npython\PluginBase\venv\lib\site-packages\sqlalchemy\pool\base.py", line 388, in __init__
    self.__connect()
  File "E:\npython\PluginBase\venv\lib\site-packages\sqlalchemy\pool\base.py", line 691, in __connect
    pool.logger.debug("Error on connect(): %s", e)
  File "E:\npython\PluginBase\venv\lib\site-packages\sqlalchemy\util\langhelpers.py", line 70, in __exit__
    compat.raise_(
  File "E:\npython\PluginBase\venv\lib\site-packages\sqlalchemy\util\compat.py", line 211, in raise_
    raise exception
  File "E:\npython\PluginBase\venv\lib\site-packages\sqlalchemy\pool\base.py", line 686, in __connect
    self.dbapi_connection = connection = pool._invoke_creator(self)
  File "E:\npython\PluginBase\venv\lib\site-packages\sqlalchemy\engine\create.py", line 574, in connect
    return dialect.connect(*cargs, **cparams)
  File "E:\npython\PluginBase\venv\lib\site-packages\sqlalchemy\engine\default.py", line 598, in connect
    return self.dbapi.connect(*cargs, **cparams)
sqlalchemy.exc.DatabaseError: (cx_Oracle.DatabaseError) ORA-12505: TNS:listener does not currently know of SID given in connect descriptor
(Background on this error at: https://sqlalche.me/e/14/4xp6)
2023-12-23 23:32:49,465 - INFO - Assets path configured: E:\npython\PluginBase\assets
2023-12-23 23:32:49,466 - INFO - Starting up TCP server on ('localhost', 62415)
2023-12-23 23:32:49,470 - INFO - App URL: tcp://localhost:62415
2023-12-23 23:32:49,470 - INFO - Connected to Flet app and handling user sessions...
2023-12-23 23:32:49,471 - INFO - Starting Flet View app...
2023-12-23 23:32:49,473 - INFO - Flet View found in: E:\npython\PluginBase\venv\lib\site-packages\flet\bin\flet\flet.exe
2023-12-23 23:32:49,737 - INFO - Session started: 
2023-12-23 23:45:36,213 - INFO - Assets path configured: E:\npython\PluginBase\assets
2023-12-23 23:45:36,214 - INFO - Starting up TCP server on ('localhost', 63564)
2023-12-23 23:45:36,219 - INFO - App URL: tcp://localhost:63564
2023-12-23 23:45:36,219 - INFO - Connected to Flet app and handling user sessions...
2023-12-23 23:45:36,219 - INFO - Starting Flet View app...
2023-12-23 23:45:36,221 - INFO - Flet View found in: E:\npython\PluginBase\venv\lib\site-packages\flet\bin\flet\flet.exe
2023-12-23 23:45:36,403 - INFO - Session started: 
